#VRML_SIM R2020a utf8
WorldInfo {
}
Viewpoint {
  orientation -0.4565748709142423 0.7210012228331115 0.5212452627341575 1.7885335538642373
  position 1.9686133633491147 4.789440808586298 0.6007635394959325
}
TexturedBackground {
}
TexturedBackgroundLight {
}
RectangleArena {
  floorSize 1 3
}
Robot {
  translation 0 0.05 -1.2
  rotation 0 0.9999999999999803 0 0
  children [
    Pen {
      inkDensity 0.75
      leadSize 0.003
    }
    DistanceSensor {
      translation 0.03 0 0.1
      rotation 0 1 0 -1.2708
      children [
        Shape {
          appearance Appearance {
            material Material {
              diffuseColor 0 0 0.8
            }
          }
          geometry Box {
            size 0.01 0.01 0.01
          }
        }
      ]
      name "ds_left"
    }
    DistanceSensor {
      translation -0.03 0 0.1
      rotation 0 1 0 -1.8708
      children [
        Shape {
          appearance Appearance {
            material Material {
              diffuseColor 0 0 0.8
            }
          }
          geometry Box {
            size 0.01 0.01 0.01
          }
        }
      ]
      name "ds_right"
    }
    DEF roboShape Shape {
      appearance Appearance {
        material Material {
          diffuseColor 0.8 0 0
        }
      }
      geometry Box {
        size 0.1 0.05 0.2
      }
    }
    HingeJoint {
      jointParameters HingeJointParameters {
        position 50.71990954764726
        anchor 0.06 0 0.05
      }
      device [
        RotationalMotor {
          name "wheel1"
        }
      ]
      endPoint DEF WHEEL1 Solid {
        translation 0.06 0 0.05
        rotation 0.21975615200088938 -0.21975695921179106 0.9504809900969873 1.621565293687235
        children [
          DEF WHEEL_SH1 Shape {
            appearance Appearance {
              material Material {
                diffuseColor 0 1 0
              }
            }
            geometry Cylinder {
              height 0.02
              radius 0.04
            }
          }
        ]
        boundingObject USE WHEEL_SH1
        physics Physics {
        }
      }
    }
    HingeJoint {
      jointParameters HingeJointParameters {
        position 12.320034279579584
        anchor -0.06 0 0.05
      }
      device [
        RotationalMotor {
          name "wheel2"
        }
      ]
      endPoint DEF WHEEL2 Solid {
        translation -0.06 0 0.05
        rotation -0.12193971802339443 -0.12194016593381132 -0.9850184267821641 1.585894356958651
        children [
          DEF WHEEL_SH2 Shape {
            appearance Appearance {
              material Material {
                diffuseColor 0 0.8 0
              }
            }
            geometry Cylinder {
              height 0.02
              radius 0.04
            }
          }
        ]
        name "solid(1)"
        boundingObject USE WHEEL_SH2
        physics Physics {
        }
      }
    }
    HingeJoint {
      jointParameters HingeJointParameters {
        position 1.8261788646748853e-07
        anchor 0.06 0 -0.05
      }
      device [
        RotationalMotor {
          name "wheel3"
        }
      ]
      endPoint DEF WHEEL3 Solid {
        translation 0.06 0 -0.05
        rotation 9.130860783788347e-08 -9.130894323374375e-08 0.9999999999999918 1.5708000000000082
        children [
          DEF WHEEL_SH3 Shape {
            appearance Appearance {
              material Material {
                diffuseColor 0 0.8 0
              }
            }
            geometry Cylinder {
              height 0.02
              radius 0.04
            }
          }
        ]
        name "solid(2)"
        boundingObject USE WHEEL_SH3
        physics Physics {
        }
      }
    }
    HingeJoint {
      jointParameters HingeJointParameters {
        position 12.320049013719437
        anchor -0.06 0 -0.05
      }
      device [
        RotationalMotor {
          name "wheel4"
        }
      ]
      endPoint DEF WHEEL4 Solid {
        translation -0.06 0 -0.05
        rotation -0.12193256923928207 -0.12193301712344025 -0.9850201966933889 1.5858925603344607
        children [
          DEF WHEEL_SH4 Shape {
            appearance Appearance {
              material Material {
                diffuseColor 0 0.8 0
              }
            }
            geometry Cylinder {
              height 0.02
              radius 0.04
            }
          }
        ]
        name "solid(3)"
        boundingObject USE WHEEL_SH4
        physics Physics {
        }
      }
    }
  ]
  boundingObject USE roboShape
  physics Physics {
  }
  controller "<extern>"
}
Solid {
  translation 0 0.01 0
  children [
    Shape {
      appearance PBRAppearance {
        metalness 0
      }
      geometry Plane {
        size 1 3
      }
    }
  ]
}
